2019-09-04 23:13:13,101 ERROR: Exception on /favicon.ico [GET] [in c:\users\tomas\appdata\local\programs\python\python36\lib\site-packages\flask\app.py:1891]
Traceback (most recent call last):
  File "c:\users\tomas\appdata\local\programs\python\python36\lib\site-packages\flask\app.py", line 2446, in wsgi_app
    response = self.full_dispatch_request()
  File "c:\users\tomas\appdata\local\programs\python\python36\lib\site-packages\flask\app.py", line 1951, in full_dispatch_request
    rv = self.handle_user_exception(e)
  File "c:\users\tomas\appdata\local\programs\python\python36\lib\site-packages\flask\app.py", line 1820, in handle_user_exception
    reraise(exc_type, exc_value, tb)
  File "c:\users\tomas\appdata\local\programs\python\python36\lib\site-packages\flask\_compat.py", line 39, in reraise
    raise value
  File "c:\users\tomas\appdata\local\programs\python\python36\lib\site-packages\flask\app.py", line 1947, in full_dispatch_request
    rv = self.preprocess_request()
  File "c:\users\tomas\appdata\local\programs\python\python36\lib\site-packages\flask\app.py", line 2241, in preprocess_request
    rv = func()
  File "C:\Users\tomas\Desktop\Python\Website-with-Flask\microblog\app\routes.py", line 16, in before_request
    g.locale = str(get_locale())
NameError: name 'g' is not defined
2019-09-04 23:14:00,635 INFO: Microblog startup [in C:\Users\tomas\Desktop\Python\Website-with-Flask\microblog\app\__init__.py:52]
2019-09-04 23:36:45,007 INFO: Microblog startup [in C:\Users\tomas\Desktop\Python\Website-with-Flask\microblog\app\__init__.py:52]
